2025-03-20 11:01:20,719 INFO    MainThread:3997891 [internal.py:wandb_internal():90] W&B internal server running at pid: 3997891, started at: 2025-03-20 11:01:20.719227
2025-03-20 11:01:20,720 INFO    WriterThread:3997891 [datastore.py:open_for_write():75] open: /media/isaac/Daten/azhar_ws/leggedOmniIsaacGymEnvs/OmniIsaacGymEnvs/omniisaacgymenvs/scripts/wandb/run-20250320_110119-AnymalTerrain_2025-03-20_11-01-15/run-AnymalTerrain_2025-03-20_11-01-15.wandb
2025-03-20 11:01:20,934 DEBUG   SenderThread:3997891 [sender.py:send():236] send: header
2025-03-20 11:01:20,934 DEBUG   SenderThread:3997891 [sender.py:send():236] send: run
2025-03-20 11:01:20,958 INFO    SenderThread:3997891 [sender.py:_maybe_setup_resume():493] checking resume status for bluewolf/rl/AnymalTerrain_2025-03-20_11-01-15
2025-03-20 11:01:21,402 ERROR   SenderThread:3997891 [internal_api.py:execute():161] 403 response executing GraphQL.
2025-03-20 11:01:21,403 ERROR   SenderThread:3997891 [internal_api.py:execute():162] {"errors":[{"message":"permission denied","path":["upsertBucket"],"extensions":{"code":"PERMISSION_ERROR"}}],"data":{"upsertBucket":null}}
2025-03-20 11:01:21,721 INFO    WriterThread:3997891 [datastore.py:close():279] close: /media/isaac/Daten/azhar_ws/leggedOmniIsaacGymEnvs/OmniIsaacGymEnvs/omniisaacgymenvs/scripts/wandb/run-20250320_110119-AnymalTerrain_2025-03-20_11-01-15/run-AnymalTerrain_2025-03-20_11-01-15.wandb
2025-03-20 11:01:21,722 INFO    HandlerThread:3997891 [handler.py:finish():806] shutting down handler
2025-03-20 11:01:21,723 ERROR   MainThread:3997891 [internal.py:wandb_internal():165] Thread SenderThread:
Traceback (most recent call last):
  File "/media/isaac/Daten/azhar_ws/isaac-sim-4.0.0/kit/python/lib/python3.10/site-packages/wandb/sdk/lib/retry.py", line 108, in __call__
    result = self._call_fn(*args, **kwargs)
  File "/media/isaac/Daten/azhar_ws/isaac-sim-4.0.0/kit/python/lib/python3.10/site-packages/wandb/sdk/internal/internal_api.py", line 158, in execute
    return self.client.execute(*args, **kwargs)
  File "/media/isaac/Daten/azhar_ws/isaac-sim-4.0.0/kit/python/lib/python3.10/site-packages/wandb/vendor/gql-0.2.0/wandb_gql/client.py", line 52, in execute
    result = self._get_result(document, *args, **kwargs)
  File "/media/isaac/Daten/azhar_ws/isaac-sim-4.0.0/kit/python/lib/python3.10/site-packages/wandb/vendor/gql-0.2.0/wandb_gql/client.py", line 60, in _get_result
    return self.transport.execute(document, *args, **kwargs)
  File "/media/isaac/Daten/azhar_ws/isaac-sim-4.0.0/kit/python/lib/python3.10/site-packages/wandb/vendor/gql-0.2.0/wandb_gql/transport/requests.py", line 39, in execute
    request.raise_for_status()
  File "/media/isaac/Daten/azhar_ws/isaac-sim-4.0.0/exts/omni.pip.cloud/pip_prebundle/requests/models.py", line 1021, in raise_for_status
    raise HTTPError(http_error_msg, response=self)
requests.exceptions.HTTPError: 403 Client Error: Forbidden for url: https://api.wandb.ai/graphql

During handling of the above exception, another exception occurred:

Traceback (most recent call last):
  File "/media/isaac/Daten/azhar_ws/isaac-sim-4.0.0/kit/python/lib/python3.10/site-packages/wandb/apis/normalize.py", line 25, in wrapper
    return func(*args, **kwargs)
  File "/media/isaac/Daten/azhar_ws/isaac-sim-4.0.0/kit/python/lib/python3.10/site-packages/wandb/sdk/internal/internal_api.py", line 1341, in upsert_run
    response = self.gql(mutation, variable_values=variable_values, **kwargs)
  File "/media/isaac/Daten/azhar_ws/isaac-sim-4.0.0/kit/python/lib/python3.10/site-packages/wandb/sdk/lib/retry.py", line 124, in __call__
    if not check_retry_fn(e):
  File "/media/isaac/Daten/azhar_ws/isaac-sim-4.0.0/kit/python/lib/python3.10/site-packages/wandb/util.py", line 887, in no_retry_auth
    raise CommError("Permission denied, ask the project owner to grant you access")
wandb.errors.CommError: Permission denied, ask the project owner to grant you access

During handling of the above exception, another exception occurred:

Traceback (most recent call last):
  File "/media/isaac/Daten/azhar_ws/isaac-sim-4.0.0/kit/python/lib/python3.10/site-packages/wandb/sdk/internal/internal_util.py", line 51, in run
    self._run()
  File "/media/isaac/Daten/azhar_ws/isaac-sim-4.0.0/kit/python/lib/python3.10/site-packages/wandb/sdk/internal/internal_util.py", line 102, in _run
    self._process(record)
  File "/media/isaac/Daten/azhar_ws/isaac-sim-4.0.0/kit/python/lib/python3.10/site-packages/wandb/sdk/internal/internal.py", line 310, in _process
    self._sm.send(record)
  File "/media/isaac/Daten/azhar_ws/isaac-sim-4.0.0/kit/python/lib/python3.10/site-packages/wandb/sdk/internal/sender.py", line 238, in send
    send_handler(record)
  File "/media/isaac/Daten/azhar_ws/isaac-sim-4.0.0/kit/python/lib/python3.10/site-packages/wandb/sdk/internal/sender.py", line 696, in send_run
    self._init_run(run, config_value_dict)
  File "/media/isaac/Daten/azhar_ws/isaac-sim-4.0.0/kit/python/lib/python3.10/site-packages/wandb/sdk/internal/sender.py", line 720, in _init_run
    server_run, inserted = self._api.upsert_run(
  File "/media/isaac/Daten/azhar_ws/isaac-sim-4.0.0/kit/python/lib/python3.10/site-packages/wandb/apis/normalize.py", line 61, in wrapper
    raise CommError(message, err).with_traceback(sys.exc_info()[2])
  File "/media/isaac/Daten/azhar_ws/isaac-sim-4.0.0/kit/python/lib/python3.10/site-packages/wandb/apis/normalize.py", line 25, in wrapper
    return func(*args, **kwargs)
  File "/media/isaac/Daten/azhar_ws/isaac-sim-4.0.0/kit/python/lib/python3.10/site-packages/wandb/sdk/internal/internal_api.py", line 1341, in upsert_run
    response = self.gql(mutation, variable_values=variable_values, **kwargs)
  File "/media/isaac/Daten/azhar_ws/isaac-sim-4.0.0/kit/python/lib/python3.10/site-packages/wandb/sdk/lib/retry.py", line 124, in __call__
    if not check_retry_fn(e):
  File "/media/isaac/Daten/azhar_ws/isaac-sim-4.0.0/kit/python/lib/python3.10/site-packages/wandb/util.py", line 887, in no_retry_auth
    raise CommError("Permission denied, ask the project owner to grant you access")
wandb.errors.CommError: Permission denied, ask the project owner to grant you access
2025-03-20 11:01:23,915 INFO    MainThread:3997891 [internal.py:handle_exit():80] Internal process exited
